Workbook

Sheet Annual P&L
A1: Ather Energy Limited — Annual P&L, Drivers & Forecast
A2: STEP 2 | Build the annual forecast from operating assumptions
A3: Particulars | B3: FY24A | C3: FY25A | D3: FY26A | E3: FY27E | F3: FY28E | G3: FY29E | I3: Forecast Assumptions | J3: FY27E | K3: FY28E | L3: FY29E
A4: Revenue from operations | B4: 1754 | C4: 2255 | D4: 3672 | E4: =D4*(1+J4) -> 5140.8 | F4: =E4*(1+K4) -> 6785.856 | G4: =F4*(1+L4) -> 8550.1786 | I4: Revenue growth | J4: 0.4 | K4: 0.32 | L4: 0.26
A5: Other income | B5: -139 | C5: 50 | D5: 146 | E5: =BS!E104 -> 177.12 | F5: =BS!F104 -> 222.93815 | G5: =BS!G104 -> 216.45773 | I5: Materials / revenue | J5: 0.71 | K5: 0.69 | L5: 0.67
A6: Total income | B6: =B4+B5 -> 1615 | C6: =C4+C5 -> 2305 | D6: =D4+D5 -> 3818 | E6: =E4+E5 -> 5317.92 | F6: =F4+F5 -> 7008.7942 | G6: =G4+G5 -> 8766.6363 | I6: Purchases / revenue | J6: 0.06 | K6: 0.06 | L6: 0.06
I7: Inventory change / revenue | J7: 0.02 | K7: 0.02 | L7: 0.02
A8: Revenue growth | C8: =C6/B6-1 -> 0.42724458 | D8: =D6/C6-1 -> 0.65639913 | E8: =E4/D4-1 -> 0.4 | F8: =F4/E4-1 -> 0.32 | G8: =G4/F4-1 -> 0.26 | I8: Employee-cost / revenue | J8: 0.11 | K8: 0.1 | L8: 0.095
I9: Other expenses / revenue | J9: 0.12 | K9: 0.09 | L9: 0.075
A10: Operating Costs | I10: Tax rate | J10: 0.25 | K10: 0.25 | L10: 0.25
A11: Materials consumed | B11: -1350 | C11: -1600 | D11: -2680 | E11: =-E4*J5 -> -3649.968 | F11: =-F4*K5 -> -4682.2406 | G11: =-G4*L5 -> -5728.6196 | I11: Dividend payout | J11: 0 | K11: 0 | L11: 0
A12: Purchases of stock-in-trade | B12: 0 | C12: -100 | D12: -180 | E12: =-E4*J6 -> -308.448 | F12: =-F4*K6 -> -407.15136 | G12: =-G4*L6 -> -513.01071
A13: Changes in inventories | B13: 0 | C13: -82 | D13: -114 | E13: =-E4*J7 -> -102.816 | F13: =-F4*K7 -> -135.71712 | G13: =-G4*L7 -> -171.00357 | I13: Exceptional items | J13: 0 | K13: 0 | L13: 0
A14: Employee expenses | B14: -260 | C14: -330 | D14: -430 | E14: =-E4*J8 -> -565.488 | F14: =-F4*K8 -> -678.5856 | G14: =-G4*L8 -> -812.26696
A15: Other expenses | B15: -828 | C15: -724 | D15: -676 | E15: =-E4*J9 -> -616.896 | F15: =-F4*K9 -> -610.72704 | G15: =-G4*L9 -> -641.26339
A16: EBITDA excluding other income | B16: =B4+SUM(B11:B15) -> -684 | C16: =C4+SUM(C11:C15) -> -581 | D16: =D4+SUM(D11:D15) -> -408 | E16: =E4+SUM(E11:E15) -> -102.816 | F16: =F4+SUM(F11:F15) -> 271.43424 | G16: =G4+SUM(G11:G15) -> 684.01428
A17: EBITDA margin | B17: =B16/B4 -> -0.38996579 | C17: =C16/C4 -> -0.25764967 | D17: =D16/D4 -> -0.11111111 | E17: =E16/E4 -> -0.02 | F17: =F16/F4 -> 0.04 | G17: =G16/G4 -> 0.08
A19: Depreciation and amortisation | B19: -147 | C19: -171 | D19: -173 | E19: =-BS!E85 -> -108.24 | F19: =-BS!F85 -> -179.07441 | G19: =-BS!G85 -> -233.69924
A20: EBIT including other income | B20: =B16+B19+B5 -> -970 | C20: =C16+C19+C5 -> -702 | D20: =D16+D19+D5 -> -435 | E20: =E16+E19+E5 -> -33.936 | F20: =F16+F19+F5 -> 315.29798 | G20: =G16+G19+G5 -> 666.77277
A21: Finance costs | B21: -89 | C21: -111 | D21: -82 | E21: =-BS!E97 -> -66.4 | F21: =-BS!F97 -> -58.33 | G21: =-BS!G97 -> -50.76
A22: PBT before exceptional items | B22: =B20+B21 -> -1059 | C22: =C20+C21 -> -813 | D22: =D20+D21 -> -517 | E22: =E20+E21 -> -100.336 | F22: =F20+F21 -> 256.96798 | G22: =G20+G21 -> 616.01277
A23: Exceptional items | B23: 0 | C23: 0 | D23: 0 | E23: =J13 -> 0 | F23: =K13 -> 0 | G23: =L13 -> 0
A24: Profit before tax | B24: =B22+B23 -> -1059 | C24: =C22+C23 -> -813 | D24: =D22+D23 -> -517 | E24: =E22+E23 -> -100.336 | F24: =F22+F23 -> 256.96798 | G24: =G22+G23 -> 616.01277
A25: Tax expense | B25: 0 | C25: 0 | D25: 0 | E25: =-MAX(0,E24)*J10 -> 0 | F25: =-MAX(0,F24)*K10 -> -64.241995 | G25: =-MAX(0,G24)*L10 -> -154.00319
A26: Profit after tax | B26: =B24+B25 -> -1059 | C26: =C24+C25 -> -813 | D26: =D24+D25 -> -517 | E26: =E24+E25 -> -100.336 | F26: =F24+F25 -> 192.72599 | G26: =G24+G25 -> 462.00958
A27: EPS (₹ / share) | B27: NM | C27: NM | D27: =D26/D29 -> -13.86059 | E27: =E26/E29 -> -2.5661381 | F27: =F26/F29 -> 4.9290533 | G27: =G26/G29 -> 11.816102
A29: Diluted shares (cr) | D29: 37.3 | E29: 39.1 | F29: 39.1 | G29: 39.1
A31: Dividend Payout | B31: 0 | C31: 0 | D31: 0 | E31: =E26*J11 -> 0 | F31: =F26*K11 -> 0 | G31: =G26*L11 -> 0
A32: P/L Transferred to Balance Sheet | B32: =B26-B31 -> -1059 | C32: =C26-C31 -> -813 | D32: =D26-D31 -> -517 | E32: =E26-E31 -> -100.336 | F32: =F26-F31 -> 192.72599 | G32: =G26-G31 -> 462.00958
A33: PAT as per Audited Statement | B33: -1059 | C33: -813 | D33: -517
A34: P&L Check | B34: =ROUND(B26-B33,2) -> 0 | C34: =ROUND(C26-C33,2) -> 0 | D34: =ROUND(D26-D33,2) -> 0

Sheet BS
A1: Ather Energy Limited — Balance Sheet & Supporting Schedules
A2: STEP 3 | Build working capital, fixed assets, debt and equity schedules
A3: Particulars | B3: FY24A | C3: FY25A | D3: FY26A | E3: FY27E | F3: FY28E | G3: FY29E
A4: Non-current Assets
A5: PPE | B5: 360 | C5: 470 | D5: 480 | E5: =E81 -> 631.6 | F5: =F81 -> 788.80508 | G5: =G81 -> 1026.3512
A6: CWIP | B6: 71 | C6: 122 | D6: 340 | E6: =E82 -> 784.008 | F6: =F82 -> 1142.5936 | G6: =G82 -> 1291.1061
A7: Investment property | B7: 0 | C7: 0 | D7: 0 | E7: =D7 -> 0 | F7: =E7 -> 0 | G7: =F7 -> 0
A8: ROU assets | B8: 65 | C8: 95 | D8: 100 | E8: =E87 -> 90.16 | F8: =F87 -> 73.880508 | G8: =G87 -> 52.635123
A9: Intangible assets | B9: 34 | C9: 51 | D9: 47 | E9: =E88 -> 47 | F9: =F88 -> 47 | G9: =G88 -> 47
A10: Investment in subsidiaries | B10: 0 | C10: 0 | D10: 0 | E10: =D10 -> 0 | F10: =E10 -> 0 | G10: =F10 -> 0
A11: Other non-current investments | B11: 0 | C11: 0 | D11: 0 | E11: =D11 -> 0 | F11: =E11 -> 0 | G11: =F11 -> 0
A12: Other non-current financial assets | B12: 0 | C12: 0 | D12: 0 | E12: =D12 -> 0 | F12: =E12 -> 0 | G12: =F12 -> 0
A13: Other non-current assets | B13: 0 | C13: 0 | D13: 200 | E13: =D13 -> 200 | F13: =E13 -> 200 | G13: =F13 -> 200
A14: Total non-current assets | B14: =SUM(B5:B13) -> 530 | C14: =SUM(C5:C13) -> 738 | D14: =SUM(D5:D13) -> 1167 | E14: =SUM(E5:E13) -> 1752.768 | F14: =SUM(F5:F13) -> 2252.2792 | G14: =SUM(G5:G13) -> 2617.0924
A16: Current Assets
A17: Inventories | B17: 185 | C17: 234 | D17: 285 | E17: =-('Annual P&L'!E11+'Annual P&L'!E12+'Annual P&L'!E13)*E66/365 -> 378.30654 | F17: =-('Annual P&L'!F11+'Annual P&L'!F12+'Annual P&L'!F13)*F66/365 -> 472.40713 | G17: =-('Annual P&L'!G11+'Annual P&L'!G12+'Annual P&L'!G13)*G66/365 -> 562.20352
A18: Current investments | B18: 292 | C18: 41 | D18: 552 | E18: =D18 -> 552 | F18: =E18 -> 552 | G18: =F18 -> 552
A19: Trade receivables | B19: 10 | C19: 12 | D19: 10 | E19: ='Annual P&L'!E4*E65/365 -> 14.084384 | F19: ='Annual P&L'!F4*F65/365 -> 18.591386 | G19: ='Annual P&L'!G4*G65/365 -> 23.425147
A20: Cash and cash equivalents | B20: 150 | C20: =CFS!C35 -> 32 | D20: =CFS!D35 -> 75 | E20: =D20+CFS!E33 -> 838.63588 | F20: =E20+CFS!F33 -> 730.62878 | G20: =F20+CFS!G33 -> 1037.7513
A21: Other bank balances | B21: 650 | C21: =1041-C18-C20 -> 968 | D21: =2952-D18-D20 -> 2325 | E21: =D21 -> 2325 | F21: =E21 -> 2325 | G21: =F21 -> 2325
A22: Other current financial assets | B22: 0 | C22: 0 | D22: 0 | E22: =D22 -> 0 | F22: =E22 -> 0 | G22: =F22 -> 0
A23: Other current assets | B23: 97 | C23: 76 | D23: 307 | E23: ='Annual P&L'!E4*E68 -> 431.8272 | F23: ='Annual P&L'!F4*F68 -> 542.86848 | G23: ='Annual P&L'!G4*G68 -> 641.26339
A24: Current tax assets | B24: 0 | C24: 0 | D24: 0 | E24: =D24 -> 0 | F24: =E24 -> 0 | G24: =F24 -> 0
A25: Total current assets | B25: =SUM(B17:B24) -> 1384 | C25: =SUM(C17:C24) -> 1363 | D25: =SUM(D17:D24) -> 3554 | E25: =SUM(E17:E24) -> 4539.854 | F25: =SUM(F17:F24) -> 4641.4958 | G25: =SUM(G17:G24) -> 5141.6433
A27: Total Assets | B27: =B14+B25 -> 1914 | C27: =C14+C25 -> 2101 | D27: =D14+D25 -> 4721 | E27: =E25+E14 -> 6292.622 | F27: =F25+F14 -> 6893.775 | G27: =G25+G14 -> 7758.7358
A30: Equity
A31: Share capital | B31: 0 | C31: 29 | D31: 38 | E31: =D31+10.8 -> 48.8 | F31: =E31 -> 48.8 | G31: =F31 -> 48.8
A32: Other equity | B32: 545 | C32: 464 | D32: 2534 | E32: =D32+'Annual P&L'!E32+1289.2 -> 3722.864 | F32: =E32+'Annual P&L'!F32 -> 3915.59 | G32: =F32+'Annual P&L'!G32 -> 4377.5996
A33: Total equity | B33: =B31+B32 -> 545 | C33: =C31+C32 -> 493 | D33: =D31+D32 -> 2572 | E33: =E31+E32 -> 3771.664 | F33: =F31+F32 -> 3964.39 | G33: =G31+G32 -> 4426.3996
A35: Non-current Liabilities
A36: Non-current lease liabilities | B36: 40 | C36: 50 | D36: 70 | E36: =D36 -> 70 | F36: =E36 -> 70 | G36: =F36 -> 70
A37: Other non-current financial liabilities | B37: 0 | C37: 0 | D37: 0 | E37: =D37 -> 0 | F37: =E37 -> 0 | G37: =F37 -> 0
A38: Non-current provisions | B38: 15 | C38: 20 | D38: 30 | E38: =D38 -> 30 | F38: =E38 -> 30 | G38: =F38 -> 30
A39: Deferred tax liabilities | B39: 0 | C39: 0 | D39: 0 | E39: =D39 -> 0 | F39: =E39 -> 0 | G39: =F39 -> 0
A40: Total non-current liabilities | B40: =SUM(B36:B39) -> 55 | C40: =SUM(C36:C39) -> 70 | D40: =SUM(D36:D39) -> 100 | E40: =SUM(E36:E39) -> 100 | F40: =SUM(F36:F39) -> 100 | G40: =SUM(G36:G39) -> 100
A42: Current Liabilities
A43: Current borrowings | B43: 478 | C43: 619 | D43: 664 | E43: =E94 -> 614 | F43: =F94 -> 564 | G43: =G94 -> 514
A44: Current lease liabilities | B44: 20 | C44: 25 | D44: 30 | E44: =D44 -> 30 | F44: =E44 -> 30 | G44: =F44 -> 30
A45: Total trade payables | B45: 388 | C45: 536 | D45: 888 | E45: =-('Annual P&L'!E11+'Annual P&L'!E12+'Annual P&L'!E13)*E67/365 -> 1201.6796 | F45: =-('Annual P&L'!F11+'Annual P&L'!F12+'Annual P&L'!F13)*F67/365 -> 1560.3751 | G45: =-('Annual P&L'!G11+'Annual P&L'!G12+'Annual P&L'!G13)*G67/365 -> 1932.5746
A46: Other current financial liabilities | B46: 70 | C46: 80 | D46: 100 | E46: =D46 -> 100 | F46: =E46 -> 100 | G46: =F46 -> 100
...

Sheet CFS
A1: Ather Energy Limited — Cash Flow Statement
A2: STEP 4 | Convert profit and balance-sheet movements into cash
A3: Particulars | B3: FY24A | C3: FY25A | D3: FY26A | E3: FY27E | F3: FY28E | G3: FY29E
A4: Profit before tax | B4: ='Annual P&L'!B24 -> -1059 | C4: ='Annual P&L'!C24 -> -813 | D4: ='Annual P&L'!D24 -> -517 | E4: ='Annual P&L'!E24 -> -100.336 | F4: ='Annual P&L'!F24 -> 256.96798 | G4: ='Annual P&L'!G24 -> 616.01277
A5: Depreciation and amortisation | B5: =-'Annual P&L'!B19 -> 147 | C5: =-'Annual P&L'!C19 -> 171 | D5: =-'Annual P&L'!D19 -> 173 | E5: =-'Annual P&L'!E19 -> 108.24 | F5: =-'Annual P&L'!F19 -> 179.07441 | G5: =-'Annual P&L'!G19 -> 233.69924
A6: Finance costs | B6: =-'Annual P&L'!B21 -> 89 | C6: =-'Annual P&L'!C21 -> 111 | D6: =-'Annual P&L'!D21 -> 82 | E6: =-'Annual P&L'!E21 -> 66.4 | F6: =-'Annual P&L'!F21 -> 58.33 | G6: =-'Annual P&L'!G21 -> 50.76
A7: Less: other income | B7: ='Annual P&L'!B5 -> -139 | C7: ='Annual P&L'!C5 -> 50 | D7: ='Annual P&L'!D5 -> 146 | E7: ='Annual P&L'!E5 -> 177.12 | F7: ='Annual P&L'!F5 -> 222.93815 | G7: ='Annual P&L'!G5 -> 216.45773
A8: Operating profit before working-capital changes | B8: =B4+B5+B6-B7 -> -684 | C8: =C4+C5+C6-C7 -> -581 | D8: =D4+D5+D6-D7 -> -408 | E8: =E4+E5+E6-E7 -> -102.816 | F8: =F4+F5+F6-F7 -> 271.43424 | G8: =G4+G5+G6-G7 -> 684.01428
A10: Change in inventories | E10: =BS!D17-BS!E17 -> -93.306542 | F10: =BS!E17-BS!F17 -> -94.100583 | G10: =BS!F17-BS!G17 -> -89.796396
A11: Change in trade receivables | E11: =BS!D19-BS!E19 -> -4.0843836 | F11: =BS!E19-BS!F19 -> -4.5070027 | G11: =BS!F19-BS!G19 -> -4.8337604
A12: Change in other current assets | E12: =BS!D23-BS!E23 -> -124.8272 | F12: =BS!E23-BS!F23 -> -111.04128 | G12: =BS!F23-BS!G23 -> -98.394912
A13: Change in trade payables | E13: =BS!E45-BS!D45 -> 313.67961 | F13: =BS!F45-BS!E45 -> 358.69545 | G13: =BS!G45-BS!F45 -> 372.19955
A14: Change in other current liabilities | E14: =BS!E47-BS!D47 -> 108.2784 | F14: =BS!F47-BS!E47 -> 99.73152 | G14: =BS!G47-BS!F47 -> 80.751686
A15: Other operating adjustments | B15: =B16-SUM(B8,B10:B14) -> 416 | C15: =C16-SUM(C8,C10:C14) -> -140 | D15: =D16-SUM(D8,D10:D14) -> 440 | E15: 0 | F15: 0 | G15: 0
A16: Cash generated from operations | B16: -268 | C16: -721 | D16: 32 | E16: =SUM(E8:E15) -> 96.923879 | F16: =SUM(F8:F15) -> 520.21234 | G16: =SUM(G8:G15) -> 943.94046
A17: Taxes paid | B17: 0 | C17: 0 | D17: 0 | E17: =-'Annual P&L'!E25 -> 0 | F17: =-'Annual P&L'!F25 -> 64.241995 | G17: =-'Annual P&L'!G25 -> 154.00319
A18: Cash flow from operations | B18: =B16-B17 -> -268 | C18: =C16-C17 -> -721 | D18: =D16-D17 -> 32 | E18: =E16-E17 -> 96.923879 | F18: =F16-F17 -> 455.97035 | G18: =G16-G17 -> 789.93726
A21: Capital expenditure | B21: -115 | C21: -339 | D21: -506 | E21: =-BS!E78 -> -694.008 | F21: =-BS!F78 -> -678.5856 | G21: =-BS!G78 -> -598.5125
A22: Other income received | B22: ='Annual P&L'!B5 -> -139 | C22: ='Annual P&L'!C5 -> 50 | D22: ='Annual P&L'!D5 -> 146 | E22: ='Annual P&L'!E5 -> 177.12 | F22: ='Annual P&L'!F5 -> 222.93815 | G22: ='Annual P&L'!G5 -> 216.45773
A23: Other investing flows | B23: =B24-B21-B22 -> 312 | C23: =C24-C21-C22 -> 189 | D23: =D24-D21-D22 -> -2126 | E23: 0 | F23: 0 | G23: 0
A24: Cash flow from investing | B24: 58 | C24: -100 | D24: -2486 | E24: =SUM(E21:E23) -> -516.888 | F24: =SUM(F21:F23) -> -455.64745 | G24: =SUM(G21:G23) -> -382.05477
A27: Change in borrowings | B27: =BS!B43-0 -> 478 | C27: =BS!C43-BS!B43 -> 141 | D27: =BS!D43-BS!C43 -> 45 | E27: =BS!E43-BS!D43 -> -50 | F27: =BS!F43-BS!E43 -> -50 | G27: =BS!G43-BS!F43 -> -50
A28: Dividends paid | B28: 0 | C28: 0 | D28: 0 | E28: =-'Annual P&L'!E31 -> 0 | F28: =-'Annual P&L'!F31 -> 0 | G28: =-'Annual P&L'!G31 -> 0
A29: Finance costs paid | B29: ='Annual P&L'!B21 -> -89 | C29: ='Annual P&L'!C21 -> -111 | D29: ='Annual P&L'!D21 -> -82 | E29: ='Annual P&L'!E21 -> -66.4 | F29: ='Annual P&L'!F21 -> -58.33 | G29: ='Annual P&L'!G21 -> -50.76
A30: Other financing flows | B30: =B31-B27-B28-B29 -> 244 | C30: =C31-C27-C28-C29 -> 673 | D30: =D31-D27-D28-D29 -> 2534 | E30: 1300 | F30: 0 | G30: 0
A31: Cash flow from financing | B31: 633 | C31: 703 | D31: 2497 | E31: =SUM(E27:E30) -> 1183.6 | F31: =SUM(F27:F30) -> -108.33 | G31: =SUM(G27:G30) -> -100.76
A33: Net change in cash | B33: =B18+B24+B31 -> 423 | C33: =C18+C24+C31 -> -118 | D33: =D18+D24+D31 -> 43 | E33: =E31+E24+E18 -> 763.63588 | F33: =F31+F24+F18 -> -108.0071 | G33: =G31+G24+G18 -> 307.12249
A34: Opening cash | B34: =B35-B33 -> -273 | C34: =B35 -> 150 | D34: =C35 -> 32 | E34: =D35 -> 75 | F34: =E35 -> 838.63588 | G34: =F35 -> 730.62878
A35: Closing cash | B35: =BS!B20 -> 150 | C35: =C34+C33 -> 32 | D35: =D34+D33 -> 75 | E35: =E34+E33 -> 838.63588 | F35: =F34+F33 -> 730.62878 | G35: =G34+G33 -> 1037.7513
A36: Cash Check | B36: =B35-BS!B20 -> 0 | C36: =C35-BS!C20 -> 0 | D36: =D35-BS!D20 -> 0 | E36: =E35-BS!E20 -> 0 | F36: =F35-BS!F20 -> 0 | G36: =G35-BS!G20 -> 0
A39: Free Cash Flow | B39: =B18+B21 -> -383 | C39: =C18+C21 -> -1060 | D39: =D18+D21 -> -474 | E39: =E18+E21 -> -597.08412 | F39: =F18+F21 -> -222.61525 | G39: =G18+G21 -> 191.42476
A40: FCF / EBITDA | B40: =B39/'Annual P&L'!B16 -> 0.55994152 | C40: =C39/'Annual P&L'!C16 -> 1.8244406 | D40: =D39/'Annual P&L'!D16 -> 1.1617647 | E40: =E39/'Annual P&L'!E16 -> 5.8073074 | F40: =F39/'Annual P&L'!F16 -> -0.82014434 | G40: =G39/'Annual P&L'!G16 -> 0.27985492

Sheet Notes
A1: Ather Energy Limited — Management Guidance & Forecast Logic
A2: STEP 1 | Separate management guidance from analyst assumptions
A3: Driver | B3: Type | C3: Management / Source Context | D3: Model Treatment | E3: FY27 Base | F3: FY28/FY29 View | G3: Source
A4: Revenue growth | B4: Analyst assumption | C4: No formal FY27 revenue guidance issued. Q1 FY27 (Jun-26) revenue grew ~59% YoY on Rizta/450-series momentum; FY26A grew 63% YoY. | D4: 40% FY27E moderating to 32%/26% as the base scales and category penetration normalises. | E4: 40% | F4: 32% / 26% analyst assumptions | G4: Q1 FY27 (Jun-26) results commentary
A5: EBITDA margin | B5: Output cross-check | C5: EBITDA margin improved from -46% (Q4 FY24) to ~-3% (Q1 FY27); management has spoken to a path toward EBITDA breakeven. | D5: Calculated — cost ratios below drive it, not set directly. | E5: Calculated (~-2%) | F5: Cost-ratio driven (~+4% / +8%) | G5: Q1 FY27 earnings call
A6: Materials / Purchases / Inventory change | B6: Analyst assumption | C6: Blended accounting gross margin was ~19% in FY26A vs. company's own 'adjusted gross margin' of 22% (Q2 FY26, ex one-offs). | D6: COGS ratio improves via LFP-cell localisation & value engineering: implied gross margin 21%→23%→25%. | E6: 79% of revenue | F6: 77% / 75% of revenue | G6: Q2 FY26 results, FY26A annual accounts
A7: Employee costs | B7: Analyst assumption | C7: Headcount scaling for Factory 3.0 ramp-up and retail network expansion. | D7: Employee cost/revenue eases from ~11% (FY26A) to ~9.5% (FY29E) as revenue outgrows headcount additions. | E7: 11.0% of revenue | F7: 10.0% / 9.5% of revenue | G7: Analyst estimate, no explicit guidance
A8: Capex | B8: Management guidance | C8: Factory 3.0 (Chhatrapati Sambhajinagar, Maharashtra) guided at ~₹927 Cr multi-year capex for phase 1+2, taking installed capacity to 1.42mn E2Ws. | D8: Capex intensity highest FY27E-28E while the plant is built, then tapers. | E8: ₹720 Cr (~14% of revenue) | F8: ₹680 Cr / ₹600 Cr | G8: IPO prospectus, Apr-2025; company capacity guidance
A9: Working capital | B9: Analyst assumption | C9: No directly comparable forecast-day guidance published. | D9: Closing-balance days calibrated to FY26A actuals (Receivable ~1d / Inventory ~35d / Payable ~109d), held broadly flat. | E9: 1d / 34d / 108d | F9: Gradual improvement to 32d / 110d by FY29E | G9: FY26A annual accounts
A10: Other income | B10: Analyst assumption | C10: FY26A other income of ₹146 Cr includes treasury income on ~₹3,000 Cr of post-IPO cash & liquid investments. | D10: Opening liquidity × ~6% yield proxy (debt mutual funds / FDs). | E10: 6.0% | F10: 6.0% / 6.0% | G10: FY26A annual accounts, treasury policy inference
A11: Exceptional items | B11: Analyst assumption | C11: No material one-off items identified in recent quarters. | D11: Set to zero throughout the forecast. | E11: Zero | F11: Zero | G11: Quarterly results review
A12: Capital raise (subsequent event) | B12: Confirmed corporate action | C12: QIP of 1,08,15,307 equity shares at ₹1,202/share (~₹1,300 Cr) allotted 15-Jul-2026, post the FY26A balance sheet date. | D12: Modeled as a one-time FY27E equity infusion (+₹1,300 Cr cash & investments, +10.8 Cr shares), which materially de-risks the Factory 3.0 funding plan. | E12: +₹1,300 Cr equity | F12: No further dilution assumed | G12: BSE filing, Ather Energy Ltd, 15-Jul-2026
A13: Tax | B13: Analyst assumption | C13: ~₹3,000+ Cr of accumulated tax losses carried forward (simplification: not separately tracked here). | D13: 25% effective rate applied only once PBT turns positive (MAX(0,PBT) basis) — conservative, likely overstates near-term cash tax given carry-forwards. | E13: 25% (if PBT>0) | F13: 25% (if PBT>0) | G13: Standard Indian corporate tax rate; simplification flagged
A14: Valuation | B14: Teaching / analyst assumption | C14: Ather is still loss-making through most of the forecast, so a pure forward P/E breaks down in the Bear case. | D14: Base/Bull: FY29E EPS × target P/E. Bear: EV/Sales cross-check shown alongside since FY29E EPS may be negative or near zero. | E14: FY29E EPS / EV-Sales | F14: Probability-weighted blend | G14: Classroom method, adapted for a pre-profit issuer

Sheet Checks
A1: Ather Energy Limited — Model Checks & Reconciliation
A2: STEP 5 | Make the three statements prove that they are linked
A3: Check | B3: FY24A | C3: FY25A | D3: FY26A | E3: FY27E | F3: FY28E | G3: FY29E
A5: P&L Check | B5: ='Annual P&L'!B34 -> 0 | C5: ='Annual P&L'!C34 -> 0 | D5: ='Annual P&L'!D34 -> 0 | E5: =IF('Annual P&L'!E34="","Not built",'Annual P&L'!E34) -> Not built | F5: =IF('Annual P&L'!F34="","Not built",'Annual P&L'!F34) -> Not built | G5: =IF('Annual P&L'!G34="","Not built",'Annual P&L'!G34) -> Not built
A6: Balance Sheet Check | B6: =BS!B55 -> 0 | C6: =BS!C55 -> -5 | D6: =BS!D55 -> 0 | E6: =IF(BS!E55="","Not built",BS!E55) -> 0 | F6: =IF(BS!F55="","Not built",BS!F55) -> 0 | G6: =IF(BS!G55="","Not built",BS!G55) -> 0
A7: Cash Check | B7: =CFS!B36 -> 0 | C7: =CFS!C36 -> 0 | D7: =CFS!D36 -> 0 | E7: =IF(CFS!E36="","Not built",CFS!E36) -> 0 | F7: =IF(CFS!F36="","Not built",CFS!F36) -> 0 | G7: =IF(CFS!G36="","Not built",CFS!G36) -> 0
A10: All three checks must be exactly zero. If a check fails, trace the linkage—never plug the difference.

Sheet Summary & Ratios
A1: Ather Energy Limited — Annual Three-Way Model Summary & Ratios
A2: STEP 6 | Read profitability, cash conversion, returns and financial position
A3: Annual Three-Way Summary
A4: Metric | B4: FY24A | C4: FY25A | D4: FY26A | E4: FY27E | F4: FY28E | G4: FY29E
A5: Revenue (₹ cr) | B5: ='Annual P&L'!B4 -> 1754 | C5: ='Annual P&L'!C4 -> 2255 | D5: ='Annual P&L'!D4 -> 3672 | E5: ='Annual P&L'!E4 -> 5140.8 | F5: ='Annual P&L'!F4 -> 6785.856 | G5: ='Annual P&L'!G4 -> 8550.1786
A6: Revenue growth | B6: ='Annual P&L'!B8 -> 0 | C6: ='Annual P&L'!C8 -> 0.42724458 | D6: ='Annual P&L'!D8 -> 0.65639913 | E6: ='Annual P&L'!E8 -> 0.4 | F6: ='Annual P&L'!F8 -> 0.32 | G6: ='Annual P&L'!G8 -> 0.26
A7: EBITDA (₹ cr) | B7: ='Annual P&L'!B16 -> -684 | C7: ='Annual P&L'!C16 -> -581 | D7: ='Annual P&L'!D16 -> -408 | E7: ='Annual P&L'!E16 -> -102.816 | F7: ='Annual P&L'!F16 -> 271.43424 | G7: ='Annual P&L'!G16 -> 684.01428
A8: EBITDA margin | B8: ='Annual P&L'!B17 -> -0.38996579 | C8: ='Annual P&L'!C17 -> -0.25764967 | D8: ='Annual P&L'!D17 -> -0.11111111 | E8: ='Annual P&L'!E17 -> -0.02 | F8: ='Annual P&L'!F17 -> 0.04 | G8: ='Annual P&L'!G17 -> 0.08
A9: PAT (₹ cr) | B9: ='Annual P&L'!B26 -> -1059 | C9: ='Annual P&L'!C26 -> -813 | D9: ='Annual P&L'!D26 -> -517 | E9: ='Annual P&L'!E26 -> -100.336 | F9: ='Annual P&L'!F26 -> 192.72599 | G9: ='Annual P&L'!G26 -> 462.00958
A10: PAT growth | C10: ='Annual P&L'!C26/'Annual P&L'!B26-1 -> -0.23229462 | D10: ='Annual P&L'!D26/'Annual P&L'!C26-1 -> -0.36408364 | E10: ='Annual P&L'!E26/'Annual P&L'!D26-1 -> -0.8059265 | F10: ='Annual P&L'!F26/'Annual P&L'!E26-1 -> -2.9208059 | G10: ='Annual P&L'!G26/'Annual P&L'!F26-1 -> 1.3972355
A11: EPS (₹ / share) | B11: ='Annual P&L'!B27 -> NM | C11: ='Annual P&L'!C27 -> NM | D11: ='Annual P&L'!D27 -> -13.86059 | E11: ='Annual P&L'!E27 -> -2.5661381 | F11: ='Annual P&L'!F27 -> 4.9290533 | G11: ='Annual P&L'!G27 -> 11.816102
A12: CFO (₹ cr) | B12: =CFS!B18 -> -268 | C12: =CFS!C18 -> -721 | D12: =CFS!D18 -> 32 | E12: =CFS!E18 -> 96.923879 | F12: =CFS!F18 -> 455.97035 | G12: =CFS!G18 -> 789.93726
A13: Free cash flow (₹ cr) | B13: =CFS!B39 -> -383 | C13: =CFS!C39 -> -1060 | D13: =CFS!D39 -> -474 | E13: =CFS!E39 -> -597.08412 | F13: =CFS!F39 -> -222.61525 | G13: =CFS!G39 -> 191.42476
A14: Cash (₹ cr) | B14: =BS!B20 -> 150 | C14: =BS!C20 -> 32 | D14: =BS!D20 -> 75 | E14: =BS!E20 -> 838.63588 | F14: =BS!F20 -> 730.62878 | G14: =BS!G20 -> 1037.7513
A15: Net debt / (cash) (₹ cr) | B15: =BS!B43-BS!B20-BS!B18-BS!B21 -> -614 | C15: =BS!C43-BS!C20-BS!C18-BS!C21 -> -422 | D15: =BS!D43-BS!D20-BS!D18-BS!D21 -> -2288 | E15: =BS!E43-BS!E20-BS!E18-BS!E21 -> -3101.6359 | F15: =BS!F43-BS!F20-BS!F18-BS!F21 -> -3043.6288 | G15: =BS!G43-BS!G20-BS!G18-BS!G21 -> -3400.7513
A16: NWC days | B16: =BS!B71 -> -81.989738 | C16: =BS!C71 -> -72.35255 | D16: =BS!D71 -> -54.968682 | E16: =BS!E71 -> -53.445 | F16: =BS!F71 -> -53.87 | G16: =BS!G71 -> -53.85
A17: ROE | B17: ='Annual P&L'!B26/BS!B33 -> -1.9431193 | C17: ='Annual P&L'!C26/AVERAGE(BS!B33,BS!C33) -> -1.566474 | D17: ='Annual P&L'!D26/AVERAGE(BS!C33,BS!D33) -> -0.33735726 | E17: ='Annual P&L'!E26/AVERAGE(BS!D33,BS!E33) -> -0.031633453 | F17: ='Annual P&L'!F26/AVERAGE(BS!E33,BS!F33) -> 0.049825398 | G17: ='Annual P&L'!G26/AVERAGE(BS!F33,BS!G33) -> 0.11012303
A18: ROCE | B18: ='Annual P&L'!B20/(BS!B33+BS!B43-BS!B20-BS!B18-BS!B21) -> 14.057971 | C18: ='Annual P&L'!C20/(BS!C33+BS!C43-BS!C20-BS!C18-BS!C21) -> -9.8873239 | D18: ='Annual P&L'!D20/(BS!D33+BS!D43-BS!D20-BS!D18-BS!D21) -> -1.5316901 | E18: ='Annual P&L'!E20/(BS!E33+BS!E43-BS!E20-BS!E18-BS!E21) -> -0.05064862 | F18: ='Annual P&L'!F20/(BS!F33+BS!F43-BS!F20-BS!F18-BS!F21) -> 0.34243187 | G18: ='Annual P&L'!G20/(BS!G33+BS!G43-BS!G20-BS!G18-BS!G21) -> 0.65009884
A19: CFO / EBITDA | B19: =CFS!B18/'Annual P&L'!B16 -> 0.39181287 | C19: =CFS!C18/'Annual P&L'!C16 -> 1.2409639 | D19: =CFS!D18/'Annual P&L'!D16 -> -0.078431373 | E19: =CFS!E18/'Annual P&L'!E16 -> -0.94269257 | F19: =CFS!F18/'Annual P&L'!F16 -> 1.6798557 | G19: =CFS!G18/'Annual P&L'!G16 -> 1.1548549
A20: FCF / EBITDA | B20: =CFS!B39/'Annual P&L'!B16 -> 0.55994152 | C20: =CFS!C39/'Annual P&L'!C16 -> 1.8244406 | D20: =CFS!D39/'Annual P&L'!D16 -> 1.1617647 | E20: =CFS!E39/'Annual P&L'!E16 -> 5.8073074 | F20: =CFS!F39/'Annual P&L'!F16 -> -0.82014434 | G20: =CFS!G39/'Annual P&L'!G16 -> 0.27985492

Sheet Scenario Valuation
A1: Ather Energy Limited — Bear / Base / Bull Scenario Valuation
A2: STEP 7 | Convert scenario EPS into probability-weighted value
A3: Market & Model Inputs
A4: Current price | B4: 1686.1 | C4: 02-Sep-2026 close (BSE); +130% YTD 2026
A5: Target year | B5: FY29E
A9: Bear / Base / Bull Valuation
A10: Scenario | B10: Probability | C10: FY29 Revenue Growth (3-yr avg) | D10: FY29 EBITDA Margin | E10: FY29 EPS | F10: Target P/E | G10: Target Price | H10: Upside / (Downside)
A11: Bear | B11: 0.25 | C11: 0.15 | D11: 0.14 | E11: =(('Annual P&L'!$D$4*(1+C11)^3)*D11-'Annual P&L'!$D$4*(1+C11)^3*0.045-BS!$D$43*0.09+BS!$D$18*0.06)*(1-0.25*((('Annual P&L'!$D$4*(1+C11)^3)*D11-'Annual P&L'!$D$4*(1+C11)^3*0.045-BS!$D$43*0.09+BS!$D$18*0.06)>0))/'Annual P&L'!$E$29 -> 9.6656401 | F11: 22 | G11: =IF(E11<=0,"NM",E11*F11) -> 212.64408 | H11: =IF(G11="NM","NM",G11/$B$4-1) -> -0.87388406
A12: Base | B12: 0.5 | C12: 0.26 | D12: 0.19 | E12: =(('Annual P&L'!$D$4*(1+C12)^3)*D12-'Annual P&L'!$D$4*(1+C12)^3*0.045-BS!$D$43*0.09+BS!$D$18*0.06)*(1-0.25*((('Annual P&L'!$D$4*(1+C12)^3)*D12-'Annual P&L'!$D$4*(1+C12)^3*0.045-BS!$D$43*0.09+BS!$D$18*0.06)>0))/'Annual P&L'!$E$29 -> 19.91893 | F12: 30 | G12: =IF(E12<=0,"NM",E12*F12) -> 597.56789 | H12: =IF(G12="NM","NM",G12/$B$4-1) -> -0.64559167
A13: Bull | B13: 0.25 | C13: 0.34 | D13: 0.24 | E13: =(('Annual P&L'!$D$4*(1+C13)^3)*D13-'Annual P&L'!$D$4*(1+C13)^3*0.045-BS!$D$43*0.09+BS!$D$18*0.06)*(1-0.25*((('Annual P&L'!$D$4*(1+C13)^3)*D13-'Annual P&L'!$D$4*(1+C13)^3*0.045-BS!$D$43*0.09+BS!$D$18*0.06)>0))/'Annual P&L'!$E$29 -> 32.536318 | F13: 38 | G13: =IF(E13<=0,"NM",E13*F13) -> 1236.3801 | H13: =IF(G13="NM","NM",G13/$B$4-1) -> -0.26672197
A17: Probability sum | B17: =SUM(B11:B13) -> 1
A18: Probability-weighted target price | B18: =B11*IF(G11="NM",B31,G11)+B12*G12+B13*G13 -> 661.03998
A19: Expected upside / (downside) | B19: =B18/$B$4-1 -> -0.60794734
A23: Each scenario changes revenue growth and EBITDA margin, calculates EPS, then applies a target P/E. This is intentionally simpler than an EV/EBITDA bridge. Working-capital and balance-sheet scenarios remain in the main model assumptions. | B23: Each scenario changes revenue growth and EBITDA margin, calculates EPS, then applies a target P/E. This is intentionally simpler than an EV/EBITDA bridge. Working-capital and balance-sheet scenarios remain in the main model assumptions. | C23: Each scenario changes revenue growth and EBITDA margin, calculates EPS, then applies a target P/E. This is intentionally simpler than an EV/EBITDA bridge. Working-capital and balance-sheet scenarios remain in the main model assumptions. | D23: Each scenario changes revenue growth and EBITDA margin, calculates EPS, then applies a target P/E. This is intentionally simpler than an EV/EBITDA bridge. Working-capital and balance-sheet scenarios remain in the main model assumptions. | E23: Each scenario changes revenue growth and EBITDA margin, calculates EPS, then applies a target P/E. This is intentionally simpler than an EV/EBITDA bridge. Working-capital and balance-sheet scenarios remain in the main model assumptions. | F23: Each scenario changes revenue growth and EBITDA margin, calculates EPS, then applies a target P/E. This is intentionally simpler than an EV/EBITDA bridge. Working-capital and balance-sheet scenarios remain in the main model assumptions. | G23: Each scenario changes revenue growth and EBITDA margin, calculates EPS, then applies a target P/E. This is intentionally simpler than an EV/EBITDA bridge. Working-capital and balance-sheet scenarios remain in the main model assumptions. | H23: Each scenario changes revenue growth and EBITDA margin, calculates EPS, then applies a target P/E. This is intentionally simpler than an EV/EBITDA bridge. Working-capital and balance-sheet scenarios remain in the main model assumptions. | I23: Each scenario changes revenue growth and EBITDA margin, calculates EPS, then applies a target P/E. This is intentionally simpler than an EV/EBITDA bridge. Working-capital and balance-sheet scenarios remain in the main model assumptions. | J23: Each scenario changes revenue growth and EBITDA margin, calculates EPS, then applies a target P/E. This is intentionally simpler than an EV/EBITDA bridge. Working-capital and balance-sheet scenarios remain in the main model assumptions.
A25: Bear-case cross-check — EV/Sales (forward P/E is NM when FY29E EPS ≤ 0)
A26: Bear FY29E Revenue (₹ Cr) | B26: ='Annual P&L'!$D$4*(1+C11)^3 -> 5584.653
A27: Applied EV/Sales multiple (peer range ~3.5x–6x for growth-stage E2W OEMs) | B27: 3.5
A28: Implied EV (₹ Cr) | B28: =B26*B27 -> 19546.286
A29: Less: FY29E net debt / (net cash), ₹ Cr (Base-case B/S trajectory used as a proxy for Bear) | B29: =BS!G43-BS!G20-BS!G18-BS!G21 -> -3400.7513
A30: Implied equity value (₹ Cr) | B30: =B28-B29 -> 22947.037
A31: Implied price / share (₹) | B31: =B30/'Annual P&L'!$E$29 -> 586.88074
A32: Implied upside / (downside) vs. current price | B32: =B31/$B$4-1 -> -0.65193005
