Workbook

Sheet FCFF Valuation
A1: Sun Pharmaceutical Industries Ltd
A2: ( SUNPHARMA | BSE Code: 524715 )
A3: Current Price (INR) | B3: 1858
A4: 52 Week High / Low (INR) | B4: 2048 | C4: 1547
A5: All figures are in INR (Cr) unless stated otherwise.
A7: Calculation of FCFF
B8: Past | C8: Forecasting
B9: Mar-26 | C9: Mar-27 | D9: Mar-28 | E9: Mar-29 | F9: Mar-30 | G9: Mar-31
A11: EBIT | B11: =ROIC!G40 -> 15457.79 | C11: =B11*(1+$B$19) -> 16076.102 | D11: =C11*(1+$B$19) -> 16719.146 | E11: =D11*(1+$B$19) -> 17387.911 | F11: =E11*(1+$B$19) -> 18083.428 | G11: =F11*(1+$B$19) -> 18806.765
A12: Tax Rate | B12: =WACC!$E$10 -> 0.2517 | C12: =WACC!$E$10 -> 0.2517 | D12: =WACC!$E$10 -> 0.2517 | E12: =WACC!$E$10 -> 0.2517 | F12: =WACC!$E$10 -> 0.2517 | G12: =WACC!$E$10 -> 0.2517
A13: EBIT*(1-T) | B13: =B11*(1-B12) -> 11567.064 | C13: =C11*(1-C12) -> 12029.747 | D13: =D11*(1-D12) -> 12510.937 | E13: =E11*(1-E12) -> 13011.374 | F13: =F11*(1-F12) -> 13531.829 | G13: =G11*(1-G12) -> 14073.102
A14: Less: Reinvestment Rate | B14: 0.219 | C14: 0.225 | D14: 0.229 | E14: 0.232 | F14: 0.235 | G14: 0.242
A15: Free Cash Flow to Firm (FCFF) | B15: =B13*(1-B14) -> 9033.8772 | C15: =C13*(1-C14) -> 9323.0538 | D15: =D13*(1-D14) -> 9645.9322 | E15: =E13*(1-E14) -> 9992.7354 | F15: =F13*(1-F14) -> 10351.849 | G15: =G13*(1-G14) -> 10667.412
A16: Mid Year Convention | C16: 0.5 | D16: =C16+1 -> 1.5 | E16: =D16+1 -> 2.5 | F16: =E16+1 -> 3.5 | G16: =F16+1 -> 4.5
A17: Discount Factor | C17: =1/(1+$B$20)^C16 -> 0.97358477 | D17: =1/(1+$B$20)^D16 -> 0.92282916 | E17: =1/(1+$B$20)^E16 -> 0.87471959 | F17: =1/(1+$B$20)^F16 -> 0.82911809 | G17: =1/(1+$B$20)^G16 -> 0.78589392
A19: Expected Growth Rate | B19: 0.04
A20: Terminal Growth Rate | B20: 0.055
A21: Weighted Average Cost of Capital | B21: =WACC!D36 -> 0.10314146
A23: Calculation of Terminal Value
A25: FCFF x (1 + Expected Growth) | B25: =G15*(1+$B$19) -> 11094.108
A26: Terminal (Growth) Rate | B26: =$B$20 -> 0.055
A27: WACC | B27: =$B$21 -> 0.10314146
A28: Terminal Value | B28: =B25/(B27-B26) -> 230448.09
A30: Calculation of Equity Value Per Share
A32: PV of FCFF (Mar-27 to Mar-31) | B32: =SUMPRODUCT(C15:G15,C17:G17) -> 43685.531
A33: PV of Terminal Value | B33: =B28*G17 -> 181107.75
A34: Value of Operating Assets | B34: =B32+B33 -> 224793.29
A35: Add: Cash | B35: 11603.08
A36: Less: Debt | B36: =WACC!C10 -> 4627.32
A37: Value of Equity | B37: =B34+B35-B36 -> 231769.05
A38: No. of Outstanding Shares (Cr) | B38: 239.93
A39: Equity Value Per Share | B39: =B37/B38 -> 965.9861
A41: Current Price of Share | B41: 1853.5
A42: Premium / (Discount) — Price / Intrinsic Value | B42: =B41/B39 -> 1.9187647

Sheet ROIC
A1: Sun Pharmaceutical Industries Ltd
A2: ( SUNPHARMA | BSE Code: 524715 )
A3: Current Price (INR) | B3: 1858
A4: 52 Week High / Low (INR) | B4: 2048 | C4: 1547
A5: All figures are in INR (Cr) unless stated otherwise.
A7: Calculation of ROIC
B8: Mar-21 | C8: Mar-22 | D8: Mar-23 | E8: Mar-24 | F8: Mar-25 | G8: Mar-26
A10: Current Assets
A11: Inventories | B11: 8997 | C11: 8925 | D11: 10513 | E11: 9868 | F11: 10243 | G11: 11493
A12: Trade Receivables | B12: 9061 | C12: 10485 | D12: 11439 | E12: 11249 | F12: 13046 | G12: 15510
A13: Loans n Advances | B13: 649 | C13: 720 | D13: 818 | E13: 855 | F13: 785 | G13: 923
A14: Other Asset Items | B14: 9737 | C14: 7812 | D14: 8309 | E14: 9206 | F14: 8918 | G14: 8282
A15: Total Current Assets | B15: =SUM(B11:B14) -> 28444 | C15: =SUM(C11:C14) -> 27942 | D15: =SUM(D11:D14) -> 31079 | E15: =SUM(E11:E14) -> 31178 | F15: =SUM(F11:F14) -> 32992 | G15: =SUM(G11:G14) -> 36208
A17: Current Liabilities
A18: Trade Payables | B18: 3974 | C18: 4490 | D18: 5682 | E18: 5653 | F18: 6184 | G18: 7334
A19: Advance from Customers | B19: 47 | C19: 29 | D19: 41 | E19: 43 | F19: 25 | G19: 137
A20: Other Liability Items | B20: 10253 | C20: 12901 | D20: 8788 | E20: 9232 | F20: 10851 | G20: 12429
A21: Total Current Liabilities | B21: =SUM(B18:B20) -> 14274 | C21: =SUM(C18:C20) -> 17420 | D21: =SUM(D18:D20) -> 14511 | E21: =SUM(E18:E20) -> 14928 | F21: =SUM(F18:F20) -> 17060 | G21: =SUM(G18:G20) -> 19900
A23: Net Working Capital | B23: =B15-B21 -> 14170 | C23: =C15-C21 -> 10522 | D23: =D15-D21 -> 16568 | E23: =E15-E21 -> 16250 | F23: =F15-F21 -> 15932 | G23: =G15-G21 -> 16308
A25: Non-Current Assets
A26: Land | B26: 642 | C26: 862 | D26: 898 | E26: 1047 | F26: 1017 | G26: 1190
A27: Building | B27: 5937 | C27: 6048 | D27: 6820 | E27: 6803 | F27: 7052 | G27: 8074
A28: Plant & Machinery | B28: 11629 | C28: 12363 | D28: 13077 | E28: 13706 | F28: 14215 | G28: 15882
A29: Equipments | B29: 273 | C29: 305 | D29: 327 | E29: 345 | F29: 368 | G29: 418
A30: Furniture n Fittings | B30: 421 | C30: 423 | D30: 444 | E30: 454 | F30: 481 | G30: 484
A31: Vehicles | B31: 371 | C31: 408 | D31: 447 | E31: 414 | F31: 478 | G31: 581
A32: Intangible Assets | B32: 15934 | C32: 6591 | D32: 8358 | E32: 8569 | F32: 8939 | G32: 9833
A33: Other Fixed Assets | B33: 371 | C33: 11707 | D33: 12729 | E33: 12983 | F33: 13399 | G33: 23859
A34: Gross Block | B34: =SUM(B26:B33) -> 35578 | C34: =SUM(C26:C33) -> 38707 | D34: =SUM(D26:D33) -> 43100 | E34: =SUM(E26:E33) -> 44321 | F34: =SUM(F26:F33) -> 45949 | G34: =SUM(G26:G33) -> 60321
A35: Accumulated Depreciation | B35: 14026 | C35: 16042 | D35: 19035 | E35: 21072 | F35: 23363 | G35: 27499
A37: Total Non-Current Assets | B37: =B34-B35 -> 21552 | C37: =C34-C35 -> 22665 | D37: =D34-D35 -> 24065 | E37: =E34-E35 -> 23249 | F37: =F34-F35 -> 22586 | G37: =G34-G35 -> 32822
A39: Invested Capital | B39: =B23+B37 -> 35722 | C39: =C23+C37 -> 33187 | D39: =D23+D37 -> 40633 | E39: =E23+E37 -> 39499 | F39: =F23+F37 -> 38518 | G39: =G23+G37 -> 49130
A40: EBIT | B40: 2940.8 | C40: 4608.67 | D40: 9580.43 | E40: 11326.36 | F40: 13983.49 | G40: 15457.79
A41: ROIC | B41: =B40/B39 -> 0.082324618 | C41: =C40/C39 -> 0.13886974 | D41: =D40/D39 -> 0.23577954 | E41: =E40/E39 -> 0.28675055 | F41: =F40/F39 -> 0.3630378 | G41: =G40/G39 -> 0.31463037
A43: Calculation of Reinvestment Rate
B44: Mar-21 | C44: Mar-22 | D44: Mar-23 | E44: Mar-24 | F44: Mar-25 | G44: Mar-26
A46: Net Capex | B46: 1073 | C46: 1434 | D46: 2065 | E46: 2171 | F46: 2068 | G46: 3513
A47: Change in Working Capital | C47: -3648 | D47: 6046 | E47: -318 | F47: -318 | G47: 376
A49: EBIT | B49: =B40 -> 2940.8 | C49: =C40 -> 4608.67 | D49: =D40 -> 9580.43 | E49: =E40 -> 11326.36 | F49: =F40 -> 13983.49 | G49: =G40 -> 15457.79
A50: Tax Rate | B50: =WACC!$E$10 -> 0.2517 | C50: =WACC!$E$10 -> 0.2517 | D50: =WACC!$E$10 -> 0.2517 | E50: =WACC!$E$10 -> 0.2517 | F50: =WACC!$E$10 -> 0.2517 | G50: =WACC!$E$10 -> 0.2517
...

Sheet WACC
A1: Sun Pharmaceutical Industries Ltd
A2: ( SUNPHARMA | BSE Code: 524715 )
A3: Current Price (INR) | B3: 1858
A4: 52 Week High / Low (INR) | B4: 2048 | C4: 1547
A5: All figures are in INR (Cr) unless stated otherwise.
A7: Weighted Average Cost of Capital
A8: Peer Company
B9: Country | C9: Total Debt | D9: Total Equity | E9: Tax Rate | F9: Debt/Equity | G9: Debt/Capital | H9: Levered Beta | I9: Unlevered Beta
A10: Sun Pharma | B10: India | C10: 4627.32 | D10: 83570.09 | E10: 0.2517 | F10: =C10/D10 -> 0.055370528 | G10: =C10/(C10+D10) -> 0.052465486 | H10: 0.63 | I10: =H10/(1+(1-E10)*F10) -> 0.60493525
A11: Torrent Pharma | B11: India | C11: 1525.5 | D11: 8388 | E11: 0.2517 | F11: =C11/D11 -> 0.18186695 | G11: =C11/(C11+D11) -> 0.15388107 | H11: 0.62 | I11: =H11/(1+(1-E11)*F11) -> 0.54573091
A12: Apollo Hospital | B12: India | C12: 8492.9 | D12: 9480 | E12: 0.2517 | F12: =C12/D12 -> 0.89587553 | G12: =C12/(C12+D12) -> 0.47253921 | H12: 0.91 | I12: =H12/(1+(1-E12)*F12) -> 0.54478502
A13: Zydus Lifesci. | B13: India | C13: 1249 | D13: 27112 | E13: 0.2517 | F13: =C13/D13 -> 0.046068162 | G13: =C13/(C13+D13) -> 0.04403935 | H13: 0.65 | I13: =H13/(1+(1-E13)*F13) -> 0.62833938
A14: Cipla | B14: India | C14: 616 | D14: 34432 | E14: 0.2517 | F14: =C14/D14 -> 0.017890335 | G14: =C14/(C14+D14) -> 0.017575896 | H14: 0.7 | I14: =H14/(1+(1-E14)*F14) -> 0.69075266
A15: Average | E15: =AVERAGE(E10:E14) -> 0.2517 | F15: =AVERAGE(F10:F14) -> 0.2394143 | G15: =AVERAGE(G10:G14) -> 0.1481002 | H15: =AVERAGE(H10:H14) -> 0.702 | I15: =AVERAGE(I10:I14) -> 0.60290865
A16: Median | E16: =MEDIAN(E10:E14) -> 0.2517 | F16: =MEDIAN(F10:F14) -> 0.055370528 | G16: =MEDIAN(G10:G14) -> 0.052465486 | H16: =MEDIAN(H10:H14) -> 0.65 | I16: =MEDIAN(I10:I14) -> 0.60493525
A18: Cost of Debt | D18: Cost of Equity
A19: Pre Tax Rate of Debt | B19: 0.0787 | D19: Risk Free Rate | E19: 0.0705
A20: Tax Rate | B20: =E10 -> 0.2517 | D20: Risk Premium Rate | E20: 0.059
A21: Post Tax Rate | B21: =B19*(1-B20) -> 0.05889121 | D21: Levered Beta | E21: =G29 -> 0.68363109
D22: Cost of Equity | E22: =E19+E21*E20 -> 0.11083423
A24: Capital Structure | F24: Levered Beta
C25: Current | D25: Target
A26: Total Debt | B26: =C10 -> 4627.32 | C26: =B26/B28 -> 0.010208923 | D26: =G15 -> 0.1481002 | F26: Comps Unlevered Beta | G26: =I16 -> 0.60493525
A27: Market Capitalisation (Cr) | B27: 448635 | C27: =B27/B28 -> 0.98979108 | D27: =1-D26 -> 0.8518998 | F27: Target Debt/Equity | G27: =D29 -> 0.17384698
A28: Total Capital | B28: =B26+B27 -> 453262.32 | C28: =C26+C27 -> 1 | D28: =D26+D27 -> 1 | F28: Tax Rate | G28: =B20 -> 0.2517
A29: Debt/Equity | C29: =B26/B27 -> 0.01031422 | D29: =D26/D27 -> 0.17384698 | F29: Levered Beta | G29: =G26*(1+(1-G28)*G27) -> 0.68363109
A32: Weighted Average Cost of Capital (WACC)
C33: Cost / Current | D33: Target Weight
A34: Debt | C34: =B21 -> 0.05889121 | D34: =D26 -> 0.1481002
A35: Equity | C35: =E22 -> 0.11083423 | D35: =D27 -> 0.8518998
A36: WACC | D36: =C34*D34+C35*D35 -> 0.10314146
A38: Notes:
A39: 1. Levered Beta is based on two-year weekly data (peer inputs).
A40: 2. Marginal tax rate used is that of the company's home country.
A41: 3. Unlevered Beta = Levered Beta / (1 + (1 - Tax Rate) x Debt/Equity).
A42: 4. Re-levered Beta = Unlevered Beta x (1 + (1 - Tax Rate) x Target Debt/Equity).
A43: 5. Target capital structure (Debt/Capital) is set equal to the peer group average.
